<?xml version="1.0" ?>
<!-- =================================================================================== -->
<!-- |    This document was autogenerated by xacro from qr_description.urdf.xacro      | -->
<!-- |    EDITING THIS FILE BY HAND IS NOT RECOMMENDED                                 | -->
<!-- =================================================================================== -->
<robot name="dragon" xmlns:xacro="http://www.ros.org/wiki/xacro">
  <!--*************************************************************-->
  <!--*********************  MACRO CONSTS  ************************-->
  <!--*************************************************************-->
  <!--***************************************************************-->
  <!--*********  VIRTUAL LINK, BODY LINK and VIRTUAL JOINT  *********-->
  <!--***************************************************************-->
  <link name="body">
    <visual>
      <geometry>
        <mesh filename="package://qr_description/meshes/body_unit_m.stl"/>
      </geometry>
      <origin rpy="1.570796349 0 1.570796349" xyz="0 0 0"/>
    </visual>
    <collision>
      <geometry>
        <box size=".1 .206 .666"/>
      </geometry>
      <origin rpy="1.570796349 0 1.570796349" xyz="-.294161 -.000952 .016932"/>
    </collision>
    <inertial>
      <mass value="9.9629698"/>
      <inertia ixx=".506565255" ixy="-.000206853" ixz="-.004881012" iyy=".516386594" iyz=".006092892" izz=".074902421"/>
      <origin rpy="1.570796349 0 1.570796349" xyz="-.294161 -.000952 .016932"/>
    </inertial>
  </link>
  <link name="fl_base">
    <visual>
      <geometry>
        <mesh filename="package://qr_description/meshes/body_part.stl"/>
      </geometry>
      <origin rpy="1.570796349 0 3.141592698" xyz="0 0 0"/>
    </visual>
    <collision>
      <geometry>
        <box size=".15 .09 .05"/>
      </geometry>
      <origin rpy="1.570796349 0 3.141592698" xyz="-0.10486 -.000933 .017767"/>
    </collision>
    <inertial>
      <mass value=".67833686"/>
      <inertia ixx=".000458198" ixy="-.000198409" ixz="-.000000564" iyy=".005121443" iyz="-.000002605" izz=".00519021"/>
      <origin rpy="1.570796349 0 3.141592698" xyz="-0.10486 -.000933 .017767"/>
    </inertial>
  </link>
  <joint name="fl_yaw" type="revolute">
    <parent link="body"/>
    <child link="fl_base"/>
    <axis xyz="1 0 0"/>
    <origin rpy="0 0 0" xyz="0 0.135 -0.045"/>
    <dynamics damping="0.01" friction="0"/>
    <limit effort="50" lower="-0.329319" upper="0.416405" velocity="1"/>
  </joint>
  <link name="fr_base">
    <visual>
      <geometry>
        <mesh filename="package://qr_description/meshes/body_part.stl"/>
      </geometry>
      <origin rpy="1.570796349 0 3.141592698" xyz="0 0 0"/>
    </visual>
    <collision>
      <geometry>
        <box size=".15 .09 .05"/>
      </geometry>
      <origin rpy="1.570796349 0 3.141592698" xyz="-0.10486 -.000933 .017767"/>
    </collision>
    <inertial>
      <mass value=".67833686"/>
      <inertia ixx=".000458198" ixy="-.000198409" ixz="-.000000564" iyy=".005121443" iyz="-.000002605" izz=".00519021"/>
      <origin rpy="1.570796349 0 3.141592698" xyz="-0.10486 -.000933 .017767"/>
    </inertial>
  </link>
  <joint name="fr_yaw" type="revolute">
    <parent link="body"/>
    <child link="fr_base"/>
    <axis xyz="1 0 0"/>
    <origin rpy="0 0 0" xyz="0 -0.135 -0.045"/>
    <dynamics damping="0.01" friction="0"/>
    <limit effort="50" lower="-0.329319" upper="0.416405" velocity="1"/>
  </joint>
  <link name="hl_base">
    <visual>
      <geometry>
        <mesh filename="package://qr_description/meshes/body_part.stl"/>
      </geometry>
      <origin rpy="1.570796349 0 0" xyz="0 0 0"/>
    </visual>
    <collision>
      <geometry>
        <box size=".15 .09 .05"/>
      </geometry>
      <origin rpy="1.570796349 0 0" xyz="0.10486 -.000933 .017767"/>
    </collision>
    <inertial>
      <mass value=".67833686"/>
      <inertia ixx=".000458198" ixy="-.000198409" ixz="-.000000564" iyy=".005121443" iyz="-.000002605" izz=".00519021"/>
      <origin rpy="1.570796349 0 0" xyz="0.10486 -.000933 .017767"/>
    </inertial>
  </link>
  <joint name="hl_yaw" type="revolute">
    <parent link="body"/>
    <child link="hl_base"/>
    <axis xyz="1 0 0"/>
    <origin rpy="0 0 0" xyz="-0.545 0.155 0.02"/>
    <dynamics damping="0.01" friction="0"/>
    <limit effort="50" lower="-0.329319" upper="0.416405" velocity="1"/>
  </joint>
  <link name="hr_base">
    <visual>
      <geometry>
        <mesh filename="package://qr_description/meshes/body_part.stl"/>
      </geometry>
      <origin rpy="1.570796349 0 0" xyz="0 0 0"/>
    </visual>
    <collision>
      <geometry>
        <box size=".15 .09 .05"/>
      </geometry>
      <origin rpy="1.570796349 0 0" xyz="0.10486 -.000933 .017767"/>
    </collision>
    <inertial>
      <mass value=".67833686"/>
      <inertia ixx=".000458198" ixy="-.000198409" ixz="-.000000564" iyy=".005121443" iyz="-.000002605" izz=".00519021"/>
      <origin rpy="1.570796349 0 0" xyz="0.10486 -.000933 .017767"/>
    </inertial>
  </link>
  <joint name="hr_yaw" type="revolute">
    <parent link="body"/>
    <child link="hr_base"/>
    <axis xyz="1 0 0"/>
    <origin rpy="0 0 0" xyz="-0.545 -0.155 0.02"/>
    <dynamics damping="0.01" friction="0"/>
    <limit effort="50" lower="-0.329319" upper="0.416405" velocity="1"/>
  </joint>
  <link name="fl_leg">
    <visual>
      <geometry>
        <mesh filename="package://qr_description/meshes/upper_leg.stl"/>
      </geometry>
      <origin rpy="1.570796349 0 3.141592698" xyz="0 0 0"/>
    </visual>
    <collision>
      <geometry>
        <box size=".098 .12 .054"/>
      </geometry>
      <origin rpy="1.570796349 0 3.141592698" xyz="-0.008484 -.001262 -.141167"/>
    </collision>
    <inertial>
      <mass value=".58240446"/>
      <inertia ixx=".004146058" ixy=".000104152" ixz="-.000001286" iyy=".000305157" iyz="-.00000174" izz=".0042282"/>
      <origin rpy="1.570796349 0 3.141592698" xyz="-0.008484 -.001262 -.141167"/>
    </inertial>
  </link>
  <joint name="fl_hip" type="revolute">
    <parent link="fl_base"/>
    <child link="fl_leg"/>
    <axis xyz="0 1 0"/>
    <origin rpy="0 0 0" xyz="0 0 0"/>
    <dynamics damping="0.01" friction="0"/>
    <limit effort="50" lower="-0.262827" upper="0.8726" velocity="1"/>
  </joint>
  <link name="fr_leg">
    <visual>
      <geometry>
        <mesh filename="package://qr_description/meshes/upper_leg.stl"/>
      </geometry>
      <origin rpy="1.570796349 0 3.141592698" xyz="0 0 0"/>
    </visual>
    <collision>
      <geometry>
        <box size=".098 .12 .054"/>
      </geometry>
      <origin rpy="1.570796349 0 3.141592698" xyz="-0.008484 -.001262 -.141167"/>
    </collision>
    <inertial>
      <mass value=".58240446"/>
      <inertia ixx=".004146058" ixy=".000104152" ixz="-.000001286" iyy=".000305157" iyz="-.00000174" izz=".0042282"/>
      <origin rpy="1.570796349 0 3.141592698" xyz="-0.008484 -.001262 -.141167"/>
    </inertial>
  </link>
  <joint name="fr_hip" type="revolute">
    <parent link="fr_base"/>
    <child link="fr_leg"/>
    <axis xyz="0 1 0"/>
    <origin rpy="0 0 0" xyz="0 0 0"/>
    <dynamics damping="0.01" friction="0"/>
    <limit effort="50" lower="-0.262827" upper="0.8726" velocity="1"/>
  </joint>
  <link name="hl_leg">
    <visual>
      <geometry>
        <mesh filename="package://qr_description/meshes/upper_leg.stl"/>
      </geometry>
      <origin rpy="1.570796349 0 0" xyz="0 0 0"/>
    </visual>
    <collision>
      <geometry>
        <box size=".098 .12 .054"/>
      </geometry>
      <origin rpy="1.570796349 0 0" xyz="0.008484 -.001262 -.141167"/>
    </collision>
    <inertial>
      <mass value=".58240446"/>
      <inertia ixx=".004146058" ixy=".000104152" ixz="-.000001286" iyy=".000305157" iyz="-.00000174" izz=".0042282"/>
      <origin rpy="1.570796349 0 0" xyz="0.008484 -.001262 -.141167"/>
    </inertial>
  </link>
  <joint name="hl_hip" type="revolute">
    <parent link="hl_base"/>
    <child link="hl_leg"/>
    <axis xyz="0 1 0"/>
    <origin rpy="0 0 0" xyz="0 0 0"/>
    <dynamics damping="0.01" friction="0"/>
    <limit effort="50" lower="-0.8726" upper="0.262827" velocity="1"/>
  </joint>
  <link name="hr_leg">
    <visual>
      <geometry>
        <mesh filename="package://qr_description/meshes/upper_leg.stl"/>
      </geometry>
      <origin rpy="1.570796349 0 0" xyz="0 0 0"/>
    </visual>
    <collision>
      <geometry>
        <box size=".098 .12 .054"/>
      </geometry>
      <origin rpy="1.570796349 0 0" xyz="0.008484 -.001262 -.141167"/>
    </collision>
    <inertial>
      <mass value=".58240446"/>
      <inertia ixx=".004146058" ixy=".000104152" ixz="-.000001286" iyy=".000305157" iyz="-.00000174" izz=".0042282"/>
      <origin rpy="1.570796349 0 0" xyz="0.008484 -.001262 -.141167"/>
    </inertial>
  </link>
  <joint name="hr_hip" type="revolute">
    <parent link="hr_base"/>
    <child link="hr_leg"/>
    <axis xyz="0 1 0"/>
    <origin rpy="0 0 0" xyz="0 0 0"/>
    <dynamics damping="0.01" friction="0"/>
    <limit effort="50" lower="-0.8726" upper="0.262827" velocity="1"/>
  </joint>
  <link name="fl_shine">
    <visual>
      <geometry>
        <mesh filename="package://qr_description/meshes/front_shine.stl"/>
      </geometry>
      <origin rpy="0 3.141592698 -1.570796349" xyz="0 0 0"/>
    </visual>
    <collision>
      <geometry>
        <box size=".022 .035995 .20"/>
      </geometry>
      <origin rpy="0 3.141592698 -1.570796349" xyz="-.000015 -.000487 -.083659"/>
    </collision>
    <inertial>
      <mass value=".29186134"/>
      <inertia ixx=".001325132" ixy="0" ixz="-.000000355" iyy=".001312476" iyz="-.000006983" izz=".000039606"/>
      <origin rpy="0 3.141592698 -1.570796349" xyz="-.000015 -.000487 -.083659"/>
    </inertial>
  </link>
  <joint name="fl_knee" type="revolute">
    <parent link="fl_leg"/>
    <child link="fl_shine"/>
    <axis xyz="0 1 0"/>
    <origin rpy="0 0 0" xyz="0 0 -0.275"/>
    <dynamics damping="0.01" friction="0"/>
    <limit effort="50" lower="-1.727748" upper="-0.595113" velocity="1"/>
  </joint>
  <link name="fr_shine">
    <visual>
      <geometry>
        <mesh filename="package://qr_description/meshes/front_shine.stl"/>
      </geometry>
      <origin rpy="0 3.141592698 -1.570796349" xyz="0 0 0"/>
    </visual>
    <collision>
      <geometry>
        <box size=".022 .035995 .20"/>
      </geometry>
      <origin rpy="0 3.141592698 -1.570796349" xyz="-.000015 -.000487 -.083659"/>
    </collision>
    <inertial>
      <mass value=".29186134"/>
      <inertia ixx=".001325132" ixy="0" ixz="-.000000355" iyy=".001312476" iyz="-.000006983" izz=".000039606"/>
      <origin rpy="0 3.141592698 -1.570796349" xyz="-.000015 -.000487 -.083659"/>
    </inertial>
  </link>
  <joint name="fr_knee" type="revolute">
    <parent link="fr_leg"/>
    <child link="fr_shine"/>
    <axis xyz="0 1 0"/>
    <origin rpy="0 0 0" xyz="0 0 -0.275"/>
    <dynamics damping="0.01" friction="0"/>
    <limit effort="50" lower="-1.727748" upper="-0.595113" velocity="1"/>
  </joint>
  <link name="hl_shine">
    <visual>
      <geometry>
        <mesh filename="package://qr_description/meshes/back_shine.stl"/>
      </geometry>
      <origin rpy="0 0 1.570796349" xyz="0 0 0"/>
    </visual>
    <collision>
      <geometry>
        <box size=".026 .043998 .24"/>
      </geometry>
      <origin rpy="0 0 1.570796349" xyz="-.000456 -.000290 -.104180"/>
    </collision>
    <inertial>
      <mass value=".29186134"/>
      <inertia ixx=".001782767" ixy="-.000000069" ixz=".000008825" iyy=".001756178" iyz="-.000011054" izz=".000048789"/>
      <origin rpy="0 0 1.570796349" xyz="-.000456 -.000290 -.104180"/>
    </inertial>
  </link>
  <joint name="hl_knee" type="revolute">
    <parent link="hl_leg"/>
    <child link="hl_shine"/>
    <axis xyz="0 1 0"/>
    <origin rpy="0 0 0" xyz="0 0 -.275"/>
    <dynamics damping="0.01" friction="0"/>
    <limit effort="50" lower="0.595113" upper="1.727748" velocity="1"/>
  </joint>
  <link name="hr_shine">
    <visual>
      <geometry>
        <mesh filename="package://qr_description/meshes/back_shine.stl"/>
      </geometry>
      <origin rpy="0 0 1.570796349" xyz="0 0 0"/>
    </visual>
    <collision>
      <geometry>
        <box size=".026 .043998 .24"/>
      </geometry>
      <origin rpy="0 0 1.570796349" xyz="-.000456 -.000290 -.104180"/>
    </collision>
    <inertial>
      <mass value=".29186134"/>
      <inertia ixx=".001782767" ixy="-.000000069" ixz=".000008825" iyy=".001756178" iyz="-.000011054" izz=".000048789"/>
      <origin rpy="0 0 1.570796349" xyz="-.000456 -.000290 -.104180"/>
    </inertial>
  </link>
  <joint name="hr_knee" type="revolute">
    <parent link="hr_leg"/>
    <child link="hr_shine"/>
    <axis xyz="0 1 0"/>
    <origin rpy="0 0 0" xyz="0 0 -.275"/>
    <dynamics damping="0.01" friction="0"/>
    <limit effort="50" lower="0.595113" upper="1.727748" velocity="1"/>
  </joint>
  <link name="fl_foot">
    <visual>
      <geometry>
        <sphere radius=".01"/>
      </geometry>
      <origin rpy="0 0 0" xyz="0 0 0"/>
    </visual>
    <collision>
      <geometry>
        <sphere radius=".01"/>
      </geometry>
      <origin rpy="0 0 0" xyz="0 0 0"/>
    </collision>
    <inertial>
      <mass value=".1"/>
      <inertia ixx=".000004" ixy="0" ixz="0" iyy=".000004" iyz="0" izz=".000004"/>
      <origin rpy="0 0 0" xyz="0 0 0"/>
    </inertial>
  </link>
  <joint name="fl_foot_fix" type="fixed">
    <parent link="fl_shine"/>
    <child link="fl_foot"/>
    <origin rpy="0 0 0" xyz="0 0 -0.226"/>
  </joint>
  <link name="fr_foot">
    <visual>
      <geometry>
        <sphere radius=".01"/>
      </geometry>
      <origin rpy="0 0 0" xyz="0 0 0"/>
    </visual>
    <collision>
      <geometry>
        <sphere radius=".01"/>
      </geometry>
      <origin rpy="0 0 0" xyz="0 0 0"/>
    </collision>
    <inertial>
      <mass value=".1"/>
      <inertia ixx=".000004" ixy="0" ixz="0" iyy=".000004" iyz="0" izz=".000004"/>
      <origin rpy="0 0 0" xyz="0 0 0"/>
    </inertial>
  </link>
  <joint name="fr_foot_fix" type="fixed">
    <parent link="fr_shine"/>
    <child link="fr_foot"/>
    <origin rpy="0 0 0" xyz="0 0 -0.226"/>
  </joint>
  <link name="hl_foot">
    <visual>
      <geometry>
        <sphere radius=".01"/>
      </geometry>
      <origin rpy="0 0 0" xyz="0 0 0"/>
    </visual>
    <collision>
      <geometry>
        <sphere radius=".01"/>
      </geometry>
      <origin rpy="0 0 0" xyz="0 0 0"/>
    </collision>
    <inertial>
      <mass value=".1"/>
      <inertia ixx=".000004" ixy="0" ixz="0" iyy=".000004" iyz="0" izz=".000004"/>
      <origin rpy="0 0 0" xyz="0 0 0"/>
    </inertial>
  </link>
  <joint name="hl_foot_fix" type="fixed">
    <parent link="hl_shine"/>
    <child link="hl_foot"/>
    <origin rpy="0 0 0" xyz="0 0 -0.266"/>
  </joint>
  <link name="hr_foot">
    <visual>
      <geometry>
        <sphere radius=".01"/>
      </geometry>
      <origin rpy="0 0 0" xyz="0 0 0"/>
    </visual>
    <collision>
      <geometry>
        <sphere radius=".01"/>
      </geometry>
      <origin rpy="0 0 0" xyz="0 0 0"/>
    </collision>
    <inertial>
      <mass value=".1"/>
      <inertia ixx=".000004" ixy="0" ixz="0" iyy=".000004" iyz="0" izz=".000004"/>
      <origin rpy="0 0 0" xyz="0 0 0"/>
    </inertial>
  </link>
  <joint name="hr_foot_fix" type="fixed">
    <parent link="hr_shine"/>
    <child link="hr_foot"/>
    <origin rpy="0 0 0" xyz="0 0 -0.266"/>
  </joint>
</robot>

